<?xml version="1.0"?>
<robot name="qbot">

  <!-- Define robot constants -->
  <!-- x-axis points forward, y-axis points to left, z-axis points upwards -->

  <!-- Robot Base -->
  <link name="base_link">
    <visual>
      <origin xyz="0 0 0" rpy="0 0 3.1415926"/>
      <geometry>
        <mesh filename="package://qbot_nodes_cpp/meshes/rover_base.stl" scale="1.0 1.0 1.0"/>
      </geometry>
      <material name="Cyan">
        <color rgba="0 1.0 1.0 1.0"/>
      </material>
    </visual>
  </link>

  <!-- Robot Footprint -->
  <link name="base_footprint"/>

  <joint name="base_joint" type="fixed">
    <parent link="base_link"/>
    <child link="base_footprint"/>
    <origin xyz="0.0 0.0 -2.0" rpy="0 0 0"/>
  </joint>

  <!-- Left Wheel -->
  <link name="drivewhl_l_link">
    <visual>
      <origin xyz="0 0 0" rpy="1.5708 0 0"/>
      <geometry>
          <cylinder radius="3.00" length="2.00"/>
      </geometry>
      <material name="Gray">
        <color rgba="0.5 0.5 0.5 1.0"/>
      </material>
    </visual>
  </link>

  <joint name="drivewhl_l_joint" type="continuous">
    <parent link="base_link"/>
    <child link="drivewhl_l_link"/>
    <origin xyz="-3.0 7.3125 1.0" rpy="0 0 0"/>
    <axis xyz="0 1 0"/>
  </joint>

    <!-- Right Wheel -->
  <link name="drivewhl_r_link">
    <visual>
      <origin xyz="0 0 0" rpy="1.5708 0 0"/>
      <geometry>
          <cylinder radius="3.00" length="2.00"/>
      </geometry>
      <material name="Gray">
        <color rgba="0.5 0.5 0.5 1.0"/>
      </material>
    </visual>
  </link>

  <joint name="drivewhl_r_joint" type="continuous">
    <parent link="base_link"/>
    <child link="drivewhl_r_link"/>
    <origin xyz="-3.0 -7.3125 1.0" rpy="0 0 0"/>
    <axis xyz="0 1 0"/>
  </joint>

  <!-- Caster Wheel -->
  <link name="front_caster">
    <visual>
      <geometry>
        <sphere radius="1.25"/>
      </geometry>
      <material name="Yellow">
        <color rgba="1.0 1.0 0 1.0"/>
      </material>
    </visual>
  </link>

  <joint name="caster_joint" type="fixed">
    <parent link="base_link"/>
    <child link="front_caster"/>
    <origin xyz="6.0 0.0 -.75" rpy="0 0 0"/>
  </joint>

</robot>